<?xml version="1.0" ?>
<robot xmlns:xacro="http://www.ros.org/wiki/xacro">

  <xacro:include filename="materials.xacro" />
  <xacro:include filename="sensorob.gazebo" />


  <link name="world">
  </link>

  <link name="base_link">
    <inertial>
      <origin xyz="0.06842933950869011 0.0009438578686686358 -0.026799613448182" rpy="0 0 0"/>
      <mass value="1.855542034998811"/>
      <inertia ixx="0.00951" iyy="0.008318" izz="0.007035" ixy="1e-05" iyz="-2.2e-05" ixz="2.3e-05"/>
    </inertial>
    <visual>
      <origin xyz="0 0 0" rpy="0 0 0"/>
      <geometry>
       <mesh filename="file://$(find sensorob_description)/meshes/base_link.stl" scale="0.001 0.001 0.001"/>
      </geometry>
      <material name="white"/>
    </visual>
    <collision>
      <origin xyz="0 0 0" rpy="0 0 0"/>
      <geometry>
       <mesh filename="file://$(find sensorob_description)/meshes/base_link.stl" scale="0.001 0.001 0.001"/>
      </geometry>
    </collision>
  </link>

  <link name="link_1">
    <inertial>
      <origin xyz="-0.019055565879578885 0.000286070591079963 0.09170345730211701" rpy="0 0 0"/>
      <mass value="2.1673778446055563"/>
      <inertia ixx="0.006709" iyy="0.007067" izz="0.005681" ixy="-7e-05" iyz="-1.2e-05" ixz="0.000853"/>
    </inertial>
    <visual>
      <origin xyz="-0.06828 -0.001091 -0.070444" rpy="0 0 0"/>
      <geometry>
       <mesh filename="file://$(find sensorob_description)/meshes/link_1.stl" scale="0.001 0.001 0.001"/>
      </geometry>
      <material name="white"/>
    </visual>
    <collision>
      <origin xyz="-0.06828 -0.001091 -0.070444" rpy="0 0 0"/>
      <geometry>
       <mesh filename="file://$(find sensorob_description)/meshes/link_1.stl" scale="0.001 0.001 0.001"/>
      </geometry>
    </collision>
  </link>

  <link name="link_2">
    <inertial>
      <origin xyz="-0.04019415358244168 -0.0010759815082936714 0.2436907782754546" rpy="0 0 0"/>
      <mass value="3.7950516594171546"/>
      <inertia ixx="0.125698" iyy="0.115802" izz="0.018463" ixy="-8.3e-05" iyz="-6.5e-05" ixz="-0.001156"/>
    </inertial>
    <visual>
      <origin xyz="0.033127 -0.001091 -0.187444" rpy="0 0 0"/>
      <geometry>
       <mesh filename="file://$(find sensorob_description)/meshes/link_2.stl" scale="0.001 0.001 0.001"/>
      </geometry>
      <material name="white"/>
    </visual>
    <collision>
      <origin xyz="0.033127 -0.001091 -0.187444" rpy="0 0 0"/>
      <geometry>
       <mesh filename="file://$(find sensorob_description)/meshes/link_2.stl" scale="0.001 0.001 0.001"/>
      </geometry>
    </collision>
  </link>

  <link name="link_3">
    <inertial>
      <origin xyz="0.03693926470328392 0.0001460307076859913 0.13201293251123314" rpy="0 0 0"/>
      <mass value="1.1351525716942115"/>
      <inertia ixx="0.007232" iyy="0.006989" izz="0.001398" ixy="7e-06" iyz="6e-06" ixz="-7.5e-05"/>
    </inertial>
    <visual>
      <origin xyz="0.001566 -0.001091 -0.612445" rpy="0 0 0"/>
      <geometry>
       <mesh filename="file://$(find sensorob_description)/meshes/link_3.stl" scale="0.001 0.001 0.001"/>
      </geometry>
      <material name="white"/>
    </visual>
    <collision>
      <origin xyz="0.001566 -0.001091 -0.612445" rpy="0 0 0"/>
      <geometry>
       <mesh filename="file://$(find sensorob_description)/meshes/link_3.stl" scale="0.001 0.001 0.001"/>
      </geometry>
    </collision>
  </link>

  <link name="link_4">
    <inertial>
      <origin xyz="0.03718105834409844 0.00018008050762574395 0.11081132606474409" rpy="0 0 0"/>
      <mass value="1.2025016995467235"/>
      <inertia ixx="0.004084" iyy="0.004612" izz="0.002169" ixy="-1e-06" iyz="-1.3e-05" ixz="-0.000638"/>
    </inertial>
    <visual>
      <origin xyz="-0.035834 -0.001091 -0.86107" rpy="0 0 0"/>
      <geometry>
       <mesh filename="file://$(find sensorob_description)/meshes/link_4.stl" scale="0.001 0.001 0.001"/>
      </geometry>
      <material name="white"/>
    </visual>
    <collision>
      <origin xyz="-0.035834 -0.001091 -0.86107" rpy="0 0 0"/>
      <geometry>
       <mesh filename="file://$(find sensorob_description)/meshes/link_4.stl" scale="0.001 0.001 0.001"/>
      </geometry>
    </collision>
  </link>

  <link name="link_5">
    <inertial>
      <origin xyz="-0.01545179087098288 -0.0004790673243868698 0.11721977365765723" rpy="0 0 0"/>
      <mass value="1.10970553090912"/>
      <inertia ixx="0.006037" iyy="0.005961" izz="0.001491" ixy="9e-06" iyz="5e-06" ixz="-0.000401"/>
    </inertial>
    <visual>
      <origin xyz="-0.008154 -0.001091 -1.004695" rpy="0 0 0"/>
      <geometry>
       <mesh filename="file://$(find sensorob_description)/meshes/link_5.stl" scale="0.001 0.001 0.001"/>
      </geometry>
      <material name="white"/>
    </visual>
    <collision>
      <origin xyz="-0.008154 -0.001091 -1.004695" rpy="0 0 0"/>
      <geometry>
       <mesh filename="file://$(find sensorob_description)/meshes/link_5.stl" scale="0.001 0.001 0.001"/>
      </geometry>
    </collision>
  </link>

  <link name="link_6">
    <inertial>
      <origin xyz="-3.087896676863544e-07 -8.620905638662135e-13 0.005353824436647114" rpy="0 0 0"/>
      <mass value="0.04766984698965481"/>
      <inertia ixx="9e-06" iyy="9e-06" izz="1.7e-05" ixy="-0.0" iyz="-0.0" ixz="0.0"/>
    </inertial>
    <visual>
      <origin xyz="0.002846 -0.001091 -1.226445" rpy="0 0 0"/>
      <geometry>
       <mesh filename="file://$(find sensorob_description)/meshes/link_6.stl" scale="0.001 0.001 0.001"/>
      </geometry>
      <material name="white"/>
    </visual>
    <collision>
      <origin xyz="0.002846 -0.001091 -1.226445" rpy="0 0 0"/>
      <geometry>
       <mesh filename="file://$(find sensorob_description)/meshes/link_6.stl" scale="0.001 0.001 0.001"/>
      </geometry>
    </collision>
  </link>

  <joint name="world_link_joint" type="fixed">
    <origin xyz="0.05 0.05 0.2" rpy="0 0 0"/>
    <parent link="world"/>
    <child link="base_link"/>
  </joint>

  <joint name="joint_1" type="revolute">
    <origin xyz="0.06828 0.001091 0.070444" rpy="0 0 0"/>
    <parent link="base_link"/>
    <child link="link_1"/>
    <axis xyz="0.0 0.0 1.0"/>
    <limit upper="2.181662" lower="-2.96706" effort="100" velocity="100"/>
  </joint>

  <joint name="joint_2" type="revolute">
    <origin xyz="-0.101407 0.0 0.117" rpy="0 0 0"/>
    <parent link="link_1"/>
    <child link="link_2"/>
    <axis xyz="-1.0 -0.0 0.0"/>
    <limit upper="2.007129" lower="-2.007129" effort="100" velocity="100"/>
  </joint>

  <joint name="joint_3" type="revolute">
    <origin xyz="0.031561 0.0 0.425001" rpy="0 0 0"/>
    <parent link="link_2"/>
    <child link="link_3"/>
    <axis xyz="1.0 0.0 -0.0"/>
    <limit upper="2.879793" lower="-2.792527" effort="100" velocity="100"/>
  </joint>

  <joint name="joint_4" type="revolute">
    <origin xyz="0.0374 0.0 0.248625" rpy="0 0 0"/>
    <parent link="link_3"/>
    <child link="link_4"/>
    <axis xyz="0.0 0.0 1.0"/>
    <limit upper="4.45059" lower="-1.658063" effort="100" velocity="100"/>
  </joint>

  <joint name="joint_5" type="revolute">
    <origin xyz="-0.02768 0.0 0.143625" rpy="0 0 0"/>
    <parent link="link_4"/>
    <child link="link_5"/>
    <axis xyz="-1.0 -0.0 -0.0"/>
    <limit upper="2.96706" lower="-2.96706" effort="100" velocity="100"/>
  </joint>

  <joint name="joint_6" type="revolute">
    <origin xyz="-0.011 0.0 0.22175" rpy="0 0 0"/>
    <parent link="link_5"/>
    <child link="link_6"/>
    <axis xyz="-0.0 0.0 1.0"/>
    <limit upper="3.141593" lower="-3.141593" effort="100" velocity="100"/>
  </joint>

</robot>
