<?xml version="1.0" ?>
<!-- =================================================================================== -->
<!-- |    This document was autogenerated by xacro from sensorob.urdf.xacro            | -->
<!-- |    EDITING THIS FILE BY HAND IS NOT RECOMMENDED                                 | -->
<!-- =================================================================================== -->
<robot name="sensorob">
  <material name="silver">
    <color rgba="0.7 0.7 0.7 1"/>
  </material>
  <material name="white">
    <color rgba="1 1 1 1"/>
  </material>
  <material name="orange">
    <color rgba="1 0.3 0.1 1"/>
  </material>
  <material name="blue">
    <color rgba="0.2 0.2 1 1"/>
  </material>
  <material name="black">
    <color rgba="0 0 0 1"/>
  </material>
  <material name="red">
    <color rgba="1 0 0 1"/>
  </material>
  <gazebo reference="base_link">
    <material>Gazebo/White</material>
    <selfCollide>true</selfCollide>
    <gravity>true</gravity>
  </gazebo>
  <gazebo reference="link_1">
    <material>Gazebo/White</material>
    <selfCollide>true</selfCollide>
  </gazebo>
  <gazebo reference="link_2">
    <material>Gazebo/White</material>
    &gt;
  
    <selfCollide>true</selfCollide>
  </gazebo>
  <gazebo reference="link_3">
    <material>Gazebo/White</material>
    <selfCollide>true</selfCollide>
  </gazebo>
  <gazebo reference="link_4">
    <material>Gazebo/White</material>
    <selfCollide>true</selfCollide>
  </gazebo>
  <gazebo reference="link_5">
    <material>Gazebo/White</material>
    <selfCollide>true</selfCollide>
  </gazebo>
  <gazebo reference="link_6">
    <material>Gazebo/White</material>
    <selfCollide>true</selfCollide>
  </gazebo>
  <link name="world">
  </link>
  <link name="base_link">
    <inertial>
      <origin rpy="0 0 0" xyz="0.0684293395086911 0.0009438578686822592 -0.026799613448182283"/>
      <mass value="1.855542034998811"/>
      <inertia ixx="0.00951" ixy="1e-05" ixz="2.3e-05" iyy="0.008318" iyz="-2.2e-05" izz="0.007035"/>
    </inertial>
    <visual>
      <origin rpy="0 0 0" xyz="0 0 0"/>
      <geometry>
        <mesh filename="file:///home/jakub/ros2_ws/install/sensorob_description/share/sensorob_description/meshes/base_link.stl" scale="0.001 0.001 0.001"/>
      </geometry>
      <material name="white"/>
    </visual>
    <collision>
      <origin rpy="0 0 0" xyz="0 0 0"/>
      <geometry>
        <mesh filename="file:///home/jakub/ros2_ws/install/sensorob_description/share/sensorob_description/meshes/base_link.stl" scale="0.001 0.001 0.001"/>
      </geometry>
    </collision>
  </link>
  <link name="link_1">
    <inertial>
      <origin rpy="0 0 0" xyz="-0.019055565879577983 0.00028607059109358383 0.0917034573021166"/>
      <mass value="2.1673778446055563"/>
      <inertia ixx="0.006709" ixy="-7e-05" ixz="0.000853" iyy="0.007067" iyz="-1.2e-05" izz="0.005681"/>
    </inertial>
    <visual>
      <origin rpy="0 0 0" xyz="-0.06828 -0.001091 -0.070444"/>
      <geometry>
        <mesh filename="file:///home/jakub/ros2_ws/install/sensorob_description/share/sensorob_description/meshes/link_1.stl" scale="0.001 0.001 0.001"/>
      </geometry>
      <material name="white"/>
    </visual>
    <collision>
      <origin rpy="0 0 0" xyz="-0.06828 -0.001091 -0.070444"/>
      <geometry>
        <mesh filename="file:///home/jakub/ros2_ws/install/sensorob_description/share/sensorob_description/meshes/link_1.stl" scale="0.001 0.001 0.001"/>
      </geometry>
    </collision>
  </link>
  <link name="link_2">
    <inertial>
      <origin rpy="0 0 0" xyz="-0.04019415358244136 -0.0010759815082800456 0.24369077827545405"/>
      <mass value="3.7950516594171546"/>
      <inertia ixx="0.125698" ixy="-8.3e-05" ixz="-0.001156" iyy="0.115802" iyz="-6.5e-05" izz="0.018463"/>
    </inertial>
    <visual>
      <origin rpy="0 0 0" xyz="0.033127 -0.001091 -0.187444"/>
      <geometry>
        <mesh filename="file:///home/jakub/ros2_ws/install/sensorob_description/share/sensorob_description/meshes/link_2.stl" scale="0.001 0.001 0.001"/>
      </geometry>
      <material name="white"/>
    </visual>
    <collision>
      <origin rpy="0 0 0" xyz="0.033127 -0.001091 -0.187444"/>
      <geometry>
        <mesh filename="file:///home/jakub/ros2_ws/install/sensorob_description/share/sensorob_description/meshes/link_2.stl" scale="0.001 0.001 0.001"/>
      </geometry>
    </collision>
  </link>
  <link name="link_3">
    <inertial>
      <origin rpy="0 0 0" xyz="0.03693926470328392 0.0001460307076859913 0.13201293251123314"/>
      <mass value="1.1351525716942115"/>
      <inertia ixx="0.007232" ixy="7e-06" ixz="-7.5e-05" iyy="0.006989" iyz="6e-06" izz="0.001398"/>
    </inertial>
    <visual>
      <origin rpy="0 0 0" xyz="0.001566 -0.001091 -0.612445"/>
      <geometry>
        <mesh filename="file:///home/jakub/ros2_ws/install/sensorob_description/share/sensorob_description/meshes/link_3.stl" scale="0.001 0.001 0.001"/>
      </geometry>
      <material name="white"/>
    </visual>
    <collision>
      <origin rpy="0 0 0" xyz="0.001566 -0.001091 -0.612445"/>
      <geometry>
        <mesh filename="file:///home/jakub/ros2_ws/install/sensorob_description/share/sensorob_description/meshes/link_3.stl" scale="0.001 0.001 0.001"/>
      </geometry>
    </collision>
  </link>
  <link name="link_4">
    <inertial>
      <origin rpy="0 0 0" xyz="0.037181058344095096 0.0001800805076532456 0.11081132606474708"/>
      <mass value="1.2025016995467235"/>
      <inertia ixx="0.004084" ixy="-1e-06" ixz="-0.000638" iyy="0.004612" iyz="-1.3e-05" izz="0.002169"/>
    </inertial>
    <visual>
      <origin rpy="0 0 0" xyz="-0.035834 -0.001091 -0.86107"/>
      <geometry>
        <mesh filename="file:///home/jakub/ros2_ws/install/sensorob_description/share/sensorob_description/meshes/link_4.stl" scale="0.001 0.001 0.001"/>
      </geometry>
      <material name="white"/>
    </visual>
    <collision>
      <origin rpy="0 0 0" xyz="-0.035834 -0.001091 -0.86107"/>
      <geometry>
        <mesh filename="file:///home/jakub/ros2_ws/install/sensorob_description/share/sensorob_description/meshes/link_4.stl" scale="0.001 0.001 0.001"/>
      </geometry>
    </collision>
  </link>
  <link name="link_5">
    <inertial>
      <origin rpy="0 0 0" xyz="-0.015451790870986186 -0.0004790673243593754 0.11721977365766034"/>
      <mass value="1.10970553090912"/>
      <inertia ixx="0.006037" ixy="9e-06" ixz="-0.000401" iyy="0.005961" iyz="5e-06" izz="0.001491"/>
    </inertial>
    <visual>
      <origin rpy="0 0 0" xyz="-0.008154 -0.001091 -1.004695"/>
      <geometry>
        <mesh filename="file:///home/jakub/ros2_ws/install/sensorob_description/share/sensorob_description/meshes/link_5.stl" scale="0.001 0.001 0.001"/>
      </geometry>
      <material name="white"/>
    </visual>
    <collision>
      <origin rpy="0 0 0" xyz="-0.008154 -0.001091 -1.004695"/>
      <geometry>
        <mesh filename="file:///home/jakub/ros2_ws/install/sensorob_description/share/sensorob_description/meshes/link_5.stl" scale="0.001 0.001 0.001"/>
      </geometry>
    </collision>
  </link>
  <link name="link_6">
    <inertial>
      <origin rpy="0 0 0" xyz="-3.0878998574747005e-07 -8.994784084226382e-13 0.005353824436650445"/>
      <mass value="0.04766984698965481"/>
      <inertia ixx="9e-06" ixy="-0.0" ixz="0.0" iyy="9e-06" iyz="-0.0" izz="1.7e-05"/>
    </inertial>
    <visual>
      <origin rpy="0 0 0" xyz="0.002846 -0.001091 -1.226445"/>
      <geometry>
        <mesh filename="file:///home/jakub/ros2_ws/install/sensorob_description/share/sensorob_description/meshes/link_6.stl" scale="0.001 0.001 0.001"/>
      </geometry>
      <material name="white"/>
    </visual>
    <collision>
      <origin rpy="0 0 0" xyz="0.002846 -0.001091 -1.226445"/>
      <geometry>
        <mesh filename="file:///home/jakub/ros2_ws/install/sensorob_description/share/sensorob_description/meshes/link_6.stl" scale="0.001 0.001 0.001"/>
      </geometry>
    </collision>
  </link>
  <joint name="world_link_joint" type="fixed">
    <origin rpy="0 0 0" xyz="0.05 0.05 0.2"/>
    <parent link="world"/>
    <child link="base_link"/>
  </joint>
  <joint name="joint_1" type="revolute">
    <origin rpy="0 0 0" xyz="0.06828 0.001091 0.070444"/>
    <parent link="base_link"/>
    <child link="link_1"/>
    <axis xyz="0.0 -0.0 1.0"/>
    <limit effort="100" lower="-3.141592653589793" upper="3.141592653589793" velocity="100"/>
    <!-- +-pi -->
  </joint>
  <joint name="joint_2" type="revolute">
    <origin rpy="0 0 0" xyz="-0.101407 0.0 0.117"/>
    <parent link="link_1"/>
    <child link="link_2"/>
    <axis xyz="-1.0 0.0 -0.0"/>
    <limit effort="100" lower="-1.570796327" upper="1.570796327" velocity="100"/>
    <!-- +-pi/2 -->
  </joint>
  <joint name="joint_3" type="revolute">
    <origin rpy="0 0 0" xyz="0.031561 0.0 0.425001"/>
    <parent link="link_2"/>
    <child link="link_3"/>
    <axis xyz="1.0 0.0 0.0"/>
    <limit effort="100" lower="-2.094395102" upper="2.094395102" velocity="100"/>
    <!-- +-2pi/3-->
  </joint>
  <joint name="joint_4" type="revolute">
    <origin rpy="0 0 0" xyz="0.0374 0.0 0.248625"/>
    <parent link="link_3"/>
    <child link="link_4"/>
    <axis xyz="0.0 0.0 1.0"/>
    <limit effort="100" lower="-3.141592653589793" upper="3.141592653589793" velocity="100"/>
    <!-- +-pi -->
  </joint>
  <joint name="joint_5" type="revolute">
    <origin rpy="0 0 0" xyz="-0.02768 0.0 0.143625"/>
    <parent link="link_4"/>
    <child link="link_5"/>
    <axis xyz="-1.0 -0.0 0.0"/>
    <limit effort="100" lower="-1.570796327" upper="1.570796327" velocity="100"/>
    <!-- +-pi/2 -->
  </joint>
  <joint name="joint_6" type="revolute">
    <origin rpy="0 0 0" xyz="-0.011 0.0 0.22175"/>
    <parent link="link_5"/>
    <child link="link_6"/>
    <axis xyz="0.0 -0.0 -1.0"/>
    <limit effort="100" lower="-6.283185307" upper="6.283185307" velocity="100"/>
    <!-- +-2pi -->
  </joint>
  <ros2_control name="GazeboSystem" type="system">
    <hardware>
      <plugin>gazebo_ros2_control/GazeboSystem</plugin>
    </hardware>
    <joint name="joint_1">
      <command_interface name="position"/>
      <command_interface name="effort"/>
      <!--            <command_interface name="velocity"/>-->
      <!--            <command_interface name="effort"/>-->
      <!--                <param name="min">-10</param>-->
      <!--                <param name="max">10</param>-->
      <state_interface name="position"/>
      <state_interface name="velocity"/>
      <state_interface name="effort"/>
    </joint>
    <joint name="joint_2">
      <command_interface name="position"/>
      <command_interface name="effort"/>
      <state_interface name="position"/>
      <state_interface name="velocity"/>
      <state_interface name="effort"/>
    </joint>
    <joint name="joint_3">
      <command_interface name="position"/>
      <command_interface name="effort"/>
      <state_interface name="position"/>
      <state_interface name="velocity"/>
      <state_interface name="effort"/>
    </joint>
    <joint name="joint_4">
      <command_interface name="position"/>
      <command_interface name="effort"/>
      <state_interface name="position"/>
      <state_interface name="velocity"/>
      <state_interface name="effort"/>
    </joint>
    <joint name="joint_5">
      <command_interface name="position"/>
      <command_interface name="effort"/>
      <state_interface name="position"/>
      <state_interface name="velocity"/>
      <state_interface name="effort"/>
    </joint>
    <joint name="joint_6">
      <command_interface name="position"/>
      <command_interface name="effort"/>
      <state_interface name="position"/>
      <state_interface name="velocity"/>
      <state_interface name="effort"/>
    </joint>
  </ros2_control>
  <gazebo>
    <plugin filename="libgazebo_ros2_control.so" name="gazebo_ros2_control">
      <parameters>/home/jakub/ros2_ws/install/sensorob/share/sensorob/config/sensorob_controllers.yaml</parameters>
    </plugin>
  </gazebo>
</robot>
