<?xml version="1.0" ?>
<!-- =================================================================================== -->
<!-- |    This document was autogenerated by xacro from sensorob.xacro                 | -->
<!-- |    EDITING THIS FILE BY HAND IS NOT RECOMMENDED                                 | -->
<!-- =================================================================================== -->
<robot name="sensorob">
  <material name="silver">
    <color rgba="0.700 0.700 0.700 1.000"/>
  </material>
  <transmission name="joint_1_tran">
    <type>transmission_interface/SimpleTransmission</type>
    <joint name="joint_1">
      <hardwareInterface>hardware_interface/EffortJointInterface</hardwareInterface>
    </joint>
    <actuator name="joint_1_actr">
      <hardwareInterface>hardware_interface/EffortJointInterface</hardwareInterface>
      <mechanicalReduction>1</mechanicalReduction>
    </actuator>
  </transmission>
  <transmission name="joint_2_tran">
    <type>transmission_interface/SimpleTransmission</type>
    <joint name="joint_2">
      <hardwareInterface>hardware_interface/EffortJointInterface</hardwareInterface>
    </joint>
    <actuator name="joint_2_actr">
      <hardwareInterface>hardware_interface/EffortJointInterface</hardwareInterface>
      <mechanicalReduction>1</mechanicalReduction>
    </actuator>
  </transmission>
  <transmission name="joint_3_tran">
    <type>transmission_interface/SimpleTransmission</type>
    <joint name="joint_3">
      <hardwareInterface>hardware_interface/EffortJointInterface</hardwareInterface>
    </joint>
    <actuator name="joint_3_actr">
      <hardwareInterface>hardware_interface/EffortJointInterface</hardwareInterface>
      <mechanicalReduction>1</mechanicalReduction>
    </actuator>
  </transmission>
  <transmission name="joint_4_tran">
    <type>transmission_interface/SimpleTransmission</type>
    <joint name="joint_4">
      <hardwareInterface>hardware_interface/EffortJointInterface</hardwareInterface>
    </joint>
    <actuator name="joint_4_actr">
      <hardwareInterface>hardware_interface/EffortJointInterface</hardwareInterface>
      <mechanicalReduction>1</mechanicalReduction>
    </actuator>
  </transmission>
  <transmission name="joint_5_tran">
    <type>transmission_interface/SimpleTransmission</type>
    <joint name="joint_5">
      <hardwareInterface>hardware_interface/EffortJointInterface</hardwareInterface>
    </joint>
    <actuator name="joint_5_actr">
      <hardwareInterface>hardware_interface/EffortJointInterface</hardwareInterface>
      <mechanicalReduction>1</mechanicalReduction>
    </actuator>
  </transmission>
  <transmission name="joint_6_tran">
    <type>transmission_interface/SimpleTransmission</type>
    <joint name="joint_6">
      <hardwareInterface>hardware_interface/EffortJointInterface</hardwareInterface>
    </joint>
    <actuator name="joint_6_actr">
      <hardwareInterface>hardware_interface/EffortJointInterface</hardwareInterface>
      <mechanicalReduction>1</mechanicalReduction>
    </actuator>
  </transmission>
  <gazebo>
    <plugin filename="libgazebo_ros2_control.so" name="control"/>
  </gazebo>
  <gazebo reference="base_link">
    <material>Gazebo/Silver</material>
    <mu1>0.2</mu1>
    <mu2>0.2</mu2>
    <selfCollide>true</selfCollide>
    <gravity>true</gravity>
  </gazebo>
  <gazebo reference="link_1_1">
    <material>Gazebo/Silver</material>
    <mu1>0.2</mu1>
    <mu2>0.2</mu2>
    <selfCollide>true</selfCollide>
  </gazebo>
  <gazebo reference="link_2_1">
    <material>Gazebo/Silver</material>
    <mu1>0.2</mu1>
    <mu2>0.2</mu2>
    <selfCollide>true</selfCollide>
  </gazebo>
  <gazebo reference="link_3_1">
    <material>Gazebo/Silver</material>
    <mu1>0.2</mu1>
    <mu2>0.2</mu2>
    <selfCollide>true</selfCollide>
  </gazebo>
  <gazebo reference="link_4_1">
    <material>Gazebo/Silver</material>
    <mu1>0.2</mu1>
    <mu2>0.2</mu2>
    <selfCollide>true</selfCollide>
  </gazebo>
  <gazebo reference="link_5_1">
    <material>Gazebo/Silver</material>
    <mu1>0.2</mu1>
    <mu2>0.2</mu2>
    <selfCollide>true</selfCollide>
  </gazebo>
  <gazebo reference="link_6_1">
    <material>Gazebo/Silver</material>
    <mu1>0.2</mu1>
    <mu2>0.2</mu2>
    <selfCollide>true</selfCollide>
  </gazebo>
  <link name="base_link">
    <inertial>
      <origin rpy="0 0 0" xyz="0.06842933950869011 0.0009438578686686358 -0.026799613448182"/>
      <mass value="1.855542034998811"/>
      <inertia ixx="0.00951" ixy="1e-05" ixz="2.3e-05" iyy="0.008318" iyz="-2.2e-05" izz="0.007035"/>
    </inertial>
    <visual>
      <origin rpy="0 0 0" xyz="0 0 0"/>
      <geometry>
        <mesh filename="package://sensorob_description/meshes/base_link.stl" scale="0.001 0.001 0.001"/>
      </geometry>
      <material name="silver"/>
    </visual>
    <collision>
      <origin rpy="0 0 0" xyz="0 0 0"/>
      <geometry>
        <mesh filename="package://sensorob_description/meshes/base_link.stl" scale="0.001 0.001 0.001"/>
      </geometry>
    </collision>
  </link>
  <link name="link_1">
    <inertial>
      <origin rpy="0 0 0" xyz="-0.017391128474433415 -0.007793862548282313 0.09170345730211693"/>
      <mass value="2.1673778446055563"/>
      <inertia ixx="0.006827" ixy="-0.000182" ixz="0.000778" iyy="0.00695" iyz="0.00035" izz="0.005681"/>
    </inertial>
    <visual>
      <origin rpy="0 0 0" xyz="-0.06828 -0.001091 -0.070444"/>
      <geometry>
        <mesh filename="package://sensorob_description/meshes/link_1.stl" scale="0.001 0.001 0.001"/>
      </geometry>
      <material name="silver"/>
    </visual>
    <collision>
      <origin rpy="0 0 0" xyz="-0.06828 -0.001091 -0.070444"/>
      <geometry>
        <mesh filename="package://sensorob_description/meshes/link_1.stl" scale="0.001 0.001 0.001"/>
      </geometry>
    </collision>
  </link>
  <link name="link_2">
    <inertial>
      <origin rpy="0 0 0" xyz="-0.03597352078588314 -0.017962304231270702 0.2436907782754546"/>
      <mass value="3.7950516594171546"/>
      <inertia ixx="0.123994" ixy="0.003737" ixz="-0.00102" iyy="0.117506" iyz="-0.000547" izz="0.018463"/>
    </inertial>
    <visual>
      <origin rpy="0 0 0" xyz="0.023626 0.041765 -0.187444"/>
      <geometry>
        <mesh filename="package://sensorob_description/meshes/link_2.stl" scale="0.001 0.001 0.001"/>
      </geometry>
      <material name="silver"/>
    </visual>
    <collision>
      <origin rpy="0 0 0" xyz="0.023626 0.041765 -0.187444"/>
      <geometry>
        <mesh filename="package://sensorob_description/meshes/link_2.stl" scale="0.001 0.001 0.001"/>
      </geometry>
    </collision>
  </link>
  <link name="link_3">
    <inertial>
      <origin rpy="0 0 0" xyz="0.03341663223535368 0.015743461072743326 0.13201293251123314"/>
      <mass value="1.1351525716942115"/>
      <inertia ixx="0.007184" ixy="9.8e-05" ixz="-7.1e-05" iyy="0.007038" iyz="-2.7e-05" izz="0.001398"/>
    </inertial>
    <visual>
      <origin rpy="0 0 0" xyz="-0.004978 0.028427 -0.612445"/>
      <geometry>
        <mesh filename="package://sensorob_description/meshes/link_3.stl" scale="0.001 0.001 0.001"/>
      </geometry>
      <material name="silver"/>
    </visual>
    <collision>
      <origin rpy="0 0 0" xyz="-0.004978 0.028427 -0.612445"/>
      <geometry>
        <mesh filename="package://sensorob_description/meshes/link_3.stl" scale="0.001 0.001 0.001"/>
      </geometry>
    </collision>
  </link>
  <link name="link_4">
    <inertial>
      <origin rpy="0 0 0" xyz="0.03362129286277545 0.015876430068886876 0.11081132606474609"/>
      <mass value="1.2025016995467235"/>
      <inertia ixx="0.004179" ixy="-0.000203" ixz="-0.000573" iyy="0.004517" iyz="-0.000281" izz="0.002169"/>
    </inertial>
    <visual>
      <origin rpy="0 0 0" xyz="-0.038874 0.012621 -0.86107"/>
      <geometry>
        <mesh filename="package://sensorob_description/meshes/link_4.stl" scale="0.001 0.001 0.001"/>
      </geometry>
      <material name="silver"/>
    </visual>
    <collision>
      <origin rpy="0 0 0" xyz="-0.038874 0.012621 -0.86107"/>
      <geometry>
        <mesh filename="package://sensorob_description/meshes/link_4.stl" scale="0.001 0.001 0.001"/>
      </geometry>
    </collision>
  </link>
  <link name="link_5">
    <inertial>
      <origin rpy="0 0 0" xyz="-0.013801299868957234 -0.00696463747478801 0.11721977365765945"/>
      <mass value="1.10970553090912"/>
      <inertia ixx="0.006017" ixy="3.4e-05" ixz="-0.000366" iyy="0.005981" iyz="-0.000165" izz="0.001491"/>
    </inertial>
    <visual>
      <origin rpy="0 0 0" xyz="-0.013787 0.024319 -1.004695"/>
      <geometry>
        <mesh filename="package://sensorob_description/meshes/link_5.stl" scale="0.001 0.001 0.001"/>
      </geometry>
      <material name="silver"/>
    </visual>
    <collision>
      <origin rpy="0 0 0" xyz="-0.013787 0.024319 -1.004695"/>
      <geometry>
        <mesh filename="package://sensorob_description/meshes/link_5.stl" scale="0.001 0.001 0.001"/>
      </geometry>
    </collision>
  </link>
  <link name="link_6">
    <inertial>
      <origin rpy="0 0 0" xyz="-3.4959433121376643e-07 -1.774095831907907e-07 0.005353824436649113"/>
      <mass value="0.04766984698965481"/>
      <inertia ixx="9e-06" ixy="0.0" ixz="0.0" iyy="9e-06" iyz="-0.0" izz="1.7e-05"/>
    </inertial>
    <visual>
      <origin rpy="0 0 0" xyz="-0.003818 0.028968 -1.226445"/>
      <geometry>
        <mesh filename="package://sensorob_description/meshes/link_6.stl" scale="0.001 0.001 0.001"/>
      </geometry>
      <material name="silver"/>
    </visual>
    <collision>
      <origin rpy="0 0 0" xyz="-0.003818 0.028968 -1.226445"/>
      <geometry>
        <mesh filename="package://sensorob_description/meshes/link_6.stl" scale="0.001 0.001 0.001"/>
      </geometry>
    </collision>
  </link>
  <joint name="joint_1" type="revolute">
    <origin rpy="0 0 0" xyz="0.06828 0.001091 0.070444"/>
    <parent link="base_link"/>
    <child link="link_1"/>
    <axis xyz="0.0 -0.0 1.0"/>
    <limit effort="100" lower="-2.96706" upper="2.181662" velocity="100"/>
  </joint>
  <joint name="joint_2" type="revolute">
    <origin rpy="0 0 0" xyz="-0.091906 -0.042856 0.117"/>
    <parent link="link_1"/>
    <child link="link_2"/>
    <axis xyz="-0.906308 -0.422618 0.0"/>
    <limit effort="100" lower="-2.007129" upper="2.007129" velocity="100"/>
  </joint>
  <joint name="joint_3" type="revolute">
    <origin rpy="0 0 0" xyz="0.028604 0.013338 0.425001"/>
    <parent link="link_2"/>
    <child link="link_3"/>
    <axis xyz="0.906308 0.422618 -0.0"/>
    <limit effort="100" lower="-2.792527" upper="2.879793" velocity="100"/>
  </joint>
  <joint name="joint_4" type="revolute">
    <origin rpy="0 0 0" xyz="0.033896 0.015806 0.248625"/>
    <parent link="link_3"/>
    <child link="link_4"/>
    <axis xyz="0.0 0.0 1.0"/>
    <limit effort="100" lower="-1.658063" upper="4.45059" velocity="100"/>
  </joint>
  <joint name="joint_5" type="revolute">
    <origin rpy="0 0 0" xyz="-0.025087 -0.011698 0.143625"/>
    <parent link="link_4"/>
    <child link="link_5"/>
    <axis xyz="-0.906308 -0.422618 -0.0"/>
    <limit effort="100" lower="-2.96706" upper="2.96706" velocity="100"/>
  </joint>
  <joint name="joint_6" type="revolute">
    <origin rpy="0 0 0" xyz="-0.009969 -0.004649 0.22175"/>
    <parent link="link_5"/>
    <child link="link_6"/>
    <axis xyz="-0.0 -0.0 1.0"/>
    <limit effort="100" lower="-3.141593" upper="3.141593" velocity="100"/>
  </joint>
</robot>
